Workbook
Name \a: '[1]FA-LISTING'!#REF!
Name \b: '[1]FA-LISTING'!#REF!
Name \c: #N/A
Name \p: '[1]FA-LISTING'!#REF!
Name _2__BCR_engine: #REF!
Name _25_pin_Cable: #REF!
Name _EMS753: #REF!
Name _er4: #REF!
Name _pn1: #REF!
Name _pn2: #REF!
Name _pn3: #REF!
Name _pn4: #REF!
Name _pn5: #REF!
Name _pn6: #REF!
Name _pn7: #REF!
Name _pn8: #REF!
Name _w1: #REF!
Name _w2: #REF!
Name A: #REF!
Name a0: #REF!
Name a100000000: #REF!
Name aaa: '[3]wsp 12-03'!$1:$1048576
Name aab: '[3]wsp 12-03'!$A:$A
Name AAP: '[4]AP Royalty table'!$F$6
Name ab: [5]Contents!#REF!
Name Abbreviation: #REF!
Name abc: #REF!
Name ACBAD: #REF!
Name actCap: #REF!
Name actEVA: #REF!
Name actOP: #REF!
Name actOth: #REF!
Name actRev: #REF!
Name AD: #REF!
Name adfasdfdfgfg: '[6]IS-01'!#REF!
Name AgedQ: #REF!
Name alicia: #REF!
Name Allocation_Last_Line: #REF!
Name Allocation_Line_Number: #REF!
Name Allocation_Pre_Tax_Royalty: #REF!
Name Allocation_Totals_Last_Col: #REF!
Name Allocation_Totals_Last_Line: #REF!
Name Allocation_Totals_Line_Number: #REF!
Name Apr_04_B: '[7]IS-01'!#REF!
Name apr_05_b: '[8]IS-01'!#REF!
Name as: '[6]IS-01'!#REF!
Name ASB: #REF!
Name asdf: '[6]IS-01'!#REF!
Name asdfasdf: '[6]IS-01'!#REF!
Name Assembly_and_Test_defect_symptom: #REF!
Name Assy_FT_Top_10: #REF!
Name at: #REF!
Name ATRAC_Not_MD_Non_Patent_LD_Totals: #REF!
Name ATRAC_Not_MD_Patent_LD_Totals: #REF!
Name Aug_08_B: '[7]IS-01'!#REF!
Name AVL: #REF!
Name AVL_1_0_20050128: #REF!
Name AVL_1_0_20050202: #REF!
Name AVL_1_0_20050622: #REF!
Name AVL_1_0_20060322: #REF!

Sheet 2026 Project
B3: SEGMENT | C3: SIZE | D3: HERO | E3: PROJECT | F3: CPU | G3: GPU | H3: PROJECT PM | I3: BM OWNER | J3: MKT NAME | K3: MODEL NAME | L3: FCS | M3: PR | N3: BM FOCUS
B4: Helios | C4: 18 | D4: 🌟🌟 | E4: Valour_ARX | F4: Intel Arrow Lake HX-R | G4: NV Board 1 | H4: Albert Pan | I4: Jackson | J4: Predator Helios 18 AI | K4: PH18-I71 | L4: ='LAPTOP 2026'!C68 -> 0 | M4: COMPUTEX | N4: 3 ROs [small qty]
B5: Helios Neo | C5: 18 | E5: iX2_ARX | F5: Intel Arrow Lake HX-R | G5: NV Board 1 + Board 2 | H5: Shao Yu Wu | J5: Predator Helios Neo 18 AI | K5: PHN18-I71 | L5: ='LAPTOP 2026'!H68 -> 46120 | M5: Follow Intel in Mar | N5: 3 ROs [small qty]
C6: 16 | E6: MacanS_ARX | F6: Intel Arrow Lake HX-R | G6: NV Board 1 + Board 2 | H6: Ken Li | I6: Yuki | J6: Predator Helios Neo 16 AI | K6: PHN16-I71 | L6: ='LAPTOP 2026'!F68 -> 46120 | M6: Follow Intel in Mar | N6: 3 [small qty]
E7: MacanS_RTX | F7: Intel Raptor Lake HX | G7: NV Board 2 | H7: Scott Hsu | J7: Predator Helios Neo 16 | K7: PHN16-I31 | L7: ='LAPTOP 2026'!G68 -> 46083 | M7: X | N7: PAP, CN, small qty
B8: Helios Neo S | C8: 16 | D8: 🌟🌟 | E8: FPACE_PTB | F8: Intel Panther Lake H484 | G8: NV Board 2 | H8: Julia Huang | I8: Yuki | J8: Predator Helios Neo 16S AI | K8: PHN16S-I51 | L8: ='LAPTOP 2026'!D68 -> 46059 | M8: CES | N8: PAP, CN
B9: Helios Neo S | E9: FPACE_ARX | F9: Intel Arrow Lake HX-R | G9: NV Board 1 + Board 2 | H9: Jessie Wang | I9: Yuki | J9: Predator Helios Neo 16S AI | K9: PHN16S-I71 | L9: ='LAPTOP 2026'!E68 -> 46112 | M9: Follow Intel in Mar | N9: US(BBY Apr on shelf), EMEA
B10: Nitro | C10: 16 | E10: Mufasa_FRX | F10: AMD Fire Range | G10: NV Board 1 + Board 2 | H10: Jessica YC Liu | J10: Acer Nitro 16 | K10: AN16-A91 | L10: ='LAPTOP 2026'!J68 -> 46178 | M10: COMPUTEX | N10: 3 ROs
E11: Mufasa_GG | F11: AMD Gorgon Point HS | G11: NV Board 2 [TBD] | H11: Jessica YC Liu | J11: Acer Nitro 16 AI | K11: AN16-A71 | L11: ='LAPTOP 2026'!I68 -> Project Canceled | N11: 3
B12: Nitro Edge [Ultra Slim] | C12: 16 | D12: 🌟🌟 | E12: Urus_Ni | F12: Nvidia N1 | G12: UMA | H12: Phoebe Chiu | J12: Acer Nitro Edge 16 AI | K12: ANE16-N51 | L12: ='LAPTOP 2026'!L68 -> 11/11/2026 (TBC) | M12: TBD | N12: EMEA, PA, PAP
B13: Nitro V | C13: 16 | E13: Picanto_PTZ | F13: Intel Panther Lake H404 | G13: NV Board 2 | H13: Scott Hsu | J13: Acer Nitro V 16 AI | K13: ANV16-I51 | L13: ='LAPTOP 2026'!N68 -> 46121 | M13: CES | N13: 3, small qty
E14: Picanto_GG | F14: AMD Gorgon Point HS | G14: NV Board 2 | H14: Wade Liu | I14: Jackson | J14: Acer Nitro V 16 AI | K14: ANV16-A71 | L14: ='LAPTOP 2026'!O68 -> 46120 | M14: CES | N14: 3
E15: Picanto_HKH | F15: AMD Hawk Point | G15: NV Board 2 | H15: Wade Liu | J15: Acer Nitro V 16 AI | K15: ANV16-A31 | L15: ='LAPTOP 2026'!Q68 -> 46120 | M15: X
E16: Picanto_RTH | F16: Intel Rapter Lake H-R | G16: NV Board 2 | H16: Phoebe Chiu | J16: Acer Nitro V 16 | K16: ANV16-I31 | L16: ='LAPTOP 2026'!P68 -> 46108 | M16: X | N16: EMEA, PA, PAP
E17: Delhi_RTX | F17: Intel Rapter Lake HX-R | G17: NV Board 2 | H17: Albert Pan | J17: Acer Nitro V 16 | K17: ANV16-I11 | L17: ='LAPTOP 2026'!T68 -> 5/E/2026 | M17: X
C18: 17.3 | E18: Sportswagon_RTH | F18: Intel Raptor Lake H-R | G18: NV Board 2 | H18: Albert Pan | J18: Acer Nitro V 17 | K18: ANV17-I31 | L18: ='LAPTOP 2026'!R68 -> 46148 | M18: X | N18: EMEA
C19: 15.6 | E19: Sportage2_RBH | F19: AMD Rarmbrandt-R 100 Series | G19: NV Board 2 | H19: Wade Liu | J19: Acer Nitro V 15 | K19: ANV15-A31 | L19: ='LAPTOP 2026'!S68 -> 46014 | M19: X | N19: 3
B20: Nitro V S | C20: 16 | D20: 🌟 | E20: Sorento_PTZ | F20: Intel Panther Lake H404 | G20: NV Board 2 | H20: Jessie Wang | J20: Acer Nitro V 16S AI | K20: ANV16S-I51 | L20: ='LAPTOP 2026'!M68 -> 46121 | M20: CES | N20: EMEA
B23: SEGMENT | C23: SIZE | D23: HERO | E23: PROJECT | F23: CPU | G23: GPU | H23: PROJECT PM | I23: BM OWNER | J23: MKT NAME | K23: MODEL NAME | L23: FCS | M23: PR | N23: BM FOCUS
B24: Atlas | C24: 7 | D24: 🌟🌟 | E24: G310_PTG | F24: Intel Panther Lake [HH] | G24: On Board | H24: Phoebe Chiu | I24: Jackson | J24: Predator Atlas 7 | K24: PA07-I51 | L24: Q3 2026 | M24: COMPUTEX | N24: EMEA
C25: 8 | E25: F900_PTG | F25: Intel Panther Lake [HH] | G25: On Board | H25: Ken Li | I25: TBD | J25: Predator Atlas 8 | K25: PA08-I51 | L25: Q3 2026 | M25: IFA GPC | N25: PAP, CN

Sheet HANDHELD 2024
B2: NITRO Blaze GN-771 | C2: ROG Ally X (2024) | D2: ROG Ally Gaming Console (2023) RC71L RC71L-ALLY.Z1X_512 | E2: ROG Ally Gaming Console (2023) RC71L RC71L-ALLY.Z1_512 | F2: MSI Claw A1M-050US | G2: MSI Claw A1M-051US | H2: MSI Claw A1M-052US | I2: MSI Claw A1M-229US | J2: Lenovo Legion Go
A3: Operating System | B3: Windows 11 Home | C3: Windows 11 Home | D3: Windows 11 Home | E3: Windows 11 Home | F3: Windows 11 Home | G3: Windows 11 Home | H3: Windows 11 Home | I3: Windows 11 Pro | J3: Windows 11 Home
A4: CPU | B4: AMD Ryzen™ 7 8840HS_x000B_(3.3GHz up to 5.1GHz, 8 Cores 16 Threads, 24MB Cache) AMD Ryzen™ AI Support total 38 TOPS | C4: AMD Ryzen™ Z1 7840U Extreme Processor ("Zen4" architecture with 4nm process, 8-core /16-threads, 24MB total cache, up to 5.10 Ghz boost) | D4: AMD Ryzen™ Z1 7840U Extreme Processor ("Zen4" architecture with 4nm process, 8-core /16-threads, 24MB total cache, up to 5.10 Ghz boost) | E4: AMD Ryzen™ Z1 Processor ("Zen4" architecture with 4nm process, 6-core /12-threads, 22MB total cache, up to 4.90 Ghz boost) | F4: Intel® Core™ Ultra 7 processor 155H with Intel® AI Boost (NPU) 16 cores (6 P-cores + 8 E-cores + 2 Low Power E-cores), Max Turbo Frequency 4.8 GHz | G4: Intel® Core™ Ultra 7 processor 155H with Intel® AI Boost (NPU) 16 cores (6 P-cores + 8 E-cores + 2 Low Power E-cores), Max Turbo Frequency 4.8 GHz | H4: Intel® Core™ Ultra 5 processor 135H with Intel® AI Boost (NPU) 14 cores (4 P-cores + 8 E-cores + 2 Low Power E-cores), Max Turbo Frequency 4.6 GHz | I4: Intel® Core™ Ultra 7 processor 155H with Intel® AI Boost (NPU) 16 cores (6 P-cores + 8 E-cores + 2 Low Power E-cores), Max Turbo Frequency 4.8 GHz | J4: AMD Ryzen Z1 Extreme
A5: GPU | B5: AMD Radeon™ 780M_x000B_(Up to 2.7GHz, AMD RDNA™ 3 12 CUs) | C5: AMD Radeon™ Graphics 780M (AMD RDNA™ 3, 12 CUs, up to 2.7 GHz, up to 8.6 Teraflops) | D5: AMD Radeon™ Graphics 780M (AMD RDNA™ 3, 12 CUs, up to 2.7 GHz, up to 8.6 Teraflops) | E5: AMD Radeon™ Graphics (AMD RDNA™ 3, 4 CUs, up to 2.5 GHz, up to 2.8 Teraflops) | F5: Intel® Arc Graphics 8 Xᵉ-Cores | G5: Intel® Arc Graphics 8 Xᵉ-Cores | H5: Intel® Arc Graphics 8 Xᵉ-Cores | I5: Intel® Arc Graphics 8 Xᵉ-Cores | J5: AMD Radeon™ Graphics
A6: TDP | B6: 10W-30W | C6: 9-30W | D6: 9-30W | E6: 9-30W
A7: Display | B7: 7-inch FHD 1920 x 1080 144Hz 500nits 10 points - touch panel_x000B_Reponse time: 7ms 100% sRGB AMD FreeSync™ Premium | C7: 7-inch FHD (1920 x 1080) 16:9 IPS-level ??? glossy display sRGB:100% Adobe:75.35% ??? Gorilla® Glass Victus™ Touch Screen (10-point multi-touch) Refresh Rate:120Hz Response Time:7ms Brightness:500nits FreeSync Premium | D7: 7-inch FHD (1920 x 1080) 16:9 IPS-level glossy display sRGB:100% Adobe:75.35% Gorilla® Glass DXC Gorilla® Glass Victus™ Touch Screen (10-point multi-touch) Refresh Rate:120Hz Response Time:7ms Brightness:500nits FreeSync Premium | E7: 7-inch FHD (1920 x 1080) 16:9 IPS-level glossy display sRGB:100% Adobe:75.35% Gorilla® Glass DXC Gorilla® Glass Victus™ Touch Screen (10-point multi-touch) Refresh Rate:120Hz Response Time:7ms Brightness:500nits FreeSync Premium | F7: 7-inch FHD(1920x1080) 16:9 IPS-level sRGB:100% Touch Screen Refresh Rate:120Hz Brightness:500nits | G7: 7-inch FHD(1920x1080) 16:9 IPS-level sRGB:100% Touch Screen Refresh Rate:120Hz Brightness:500nits | H7: 7-inch FHD(1920x1080) 16:9 IPS-level sRGB:100% Touch Screen Refresh Rate:120Hz Brightness:500nits | I7: 7-inch FHD(1920x1080) 16:9 IPS-level sRGB:100% Touch Screen Refresh Rate:120Hz Brightness:500nits | J7: 8.8-inch QHD (2560 x 1600) IPS, 500 nits 16:10 aspect ratio 144Hz refresh rate 97% DCI-P3 10-point touchscreen Gorilla® Glass
A8: Memory | B8: 16GB LPDDR5x 7500MHz (onboard) | C8: 12GB*2 LPDDR5 on board Support dual channel memory | D8: 16GB LPDDR5 on board (6400MT/s dual channel) | E8: 16GB LPDDR5 on board (6400MT/s dual channel) | F8: 16GB LPDDR5-6400MHz | G8: 16GB LPDDR5-6400MHz | H8: 16GB LPDDR5-6400MHz | I8: 16GB LPDDR5-6400MHz | J8: 16GB 7500Mhz LPDDR5X (onboard)
A9: Storage | B9: 512GB M.2 2280 NVMe™ PCIe® 4.0 x4 Gen 4 SSD up to 2TB | C9: 1TB PCIe® 4.0 NVMe™ M.2 SSD (2280) | D9: 512GB PCIe® 4.0 NVMe™ M.2 SSD (2230) | E9: 512GB PCIe® 4.0 NVMe™ M.2 SSD (2230) | F9: 1TB NVMe SSD Gen4x4 2230 | G9: 512GB NVMe SSD Gen4x4 2230 | H9: 512GB NVMe SSD Gen4x4 2230 | I9: 1TB NVMe SSD Gen4x4 2230 | J9: Up to 1TB PCIe 4.0 NVMe M.2 2242
A10: I/O Ports | B10: 2 x Type-C 40Gbps_x000B_ Micro SD Card (SD4.0) | C10: 1x 3.5mm Combo Audio Jack 1x USB 3.2 Gen 2 Type-C support DisplayPort™ / power delivery 1x Type C support USB 4 (Thunderbolt™ 4 compliance, DisplayPort™ 1.4 with Freesync support, Power Delivery 3.0) 1x UHS-II microSD card reader (supports SD, SDXC and SDHC) | D10: 1x 3.5mm Combo Audio Jack 1x ROG XG Mobile Interface and USB Type-C combo port (with USB 3.2 Gen2, support DisplayPort™ 1.4) 1x UHS-II microSD card reader (supports SD, SDXC and SDHC) | E10: 1x 3.5mm Combo Audio Jack 1x ROG XG Mobile Interface and USB Type-C combo port (with USB 3.2 Gen2, support DisplayPort™ 1.4) 1x UHS-II microSD card reader (supports SD, SDXC and SDHC) | F10: 1x Audio Combo (1/8") 1x Thunderbolt™ 4 1x HDMI card reader:SD4.0 | G10: 1x Audio Combo (1/8") 1x Thunderbolt™ 4 1x HDMI card reader:SD4.0 | H10: 1x Audio Combo (1/8") 1x Thunderbolt™ 4 1x HDMI card reader:SD4.0 | I10: 1x Audio Combo (1/8") 1x Thunderbolt™ 4 1x HDMI card reader:SD4.0 | J10: 1x Headphone / mic combo 2x USB-C 4.0 (DisplayPort™ 1.4, Power Delivery 3.0) 1x MicroSD card reader (supports up to 2TB)
A11: Control and Input | B11: A B X Y D-Pad LB/RB Bumpers LS/RS Sticks LT/RT Hall linear triggers Power-on button support fingerprint power-on Volume button Select button Start button Home button (Long press XBOX key) Pop-up keyboard button Quick button (Long press Game Assistant Energy Saving button | C11: A B X Y buttons D-pad ??? L & R Hall Effect analog triggers L & R bumpers View button Menu button Command Center button Armoury Crate button ??? 2 x assignable grip buttons Thumbsticks: 2 x full-size analog sticks Haptics: HD haptics ??? Gyro:6-Axis IMU ??? | D11: A B X Y buttons D-pad L & R Hall Effect analog triggers L & R bumpers View button Menu button Command Center button Armoury Crate button 2 x assignable grip buttons Thumbsticks: 2 x full-size analog sticks Haptics: HD haptics Gyro:6-Axis IMU | E11: A B X Y buttons D-pad L & R Hall Effect analog triggers L & R bumpers View button Menu button Command Center button Armoury Crate button 2 x assignable grip buttons Thumbsticks: 2 x full-size analog sticks Haptics: HD haptics Gyro:6-Axis IMU | F11: Hall Effect Joysticks and Triggers??? | G11: Hall Effect Joysticks and Triggers | H11: Hall Effect Joysticks and Triggers | I11: Hall Effect Joysticks and Triggers | J11: Legion L/R ABXY buttons D-pad L & R hall effect joysticks L & R bumpers L & R analog triggers Legion L & R buttons View button (L) Menu button (L) Trackpad (R) 6x assignable grip buttons Mouse wheel (R) Mouse sensor (R) 2x controllers release buttons Haptics: HD Haptics Gyro: 6-Axis IMU
A12: Audio | B12: Speaker: 2 x 1W Microphone: 2 x D-MIC Audio Jack: 3.5mm CTIA | C12: AI noise-canceling technology Hi-Res certification (for headphone) Smart Amp Technology ??? Dolby Atmos Built-in array microphone 2-speaker system with Smart Amplifier Technology | D12: AI noise-canceling technology Hi-Res certification (for headphone) Dolby Atmos Built-in array microphone 2-speaker system with Smart Amplifier Technology | E12: AI noise-canceling technology Hi-Res certification (for headphone) Dolby Atmos Built-in array microphone 2-speaker system with Smart Amplifier Technology | F12: 2x2W Speakers Hi-Res | G12: 2x2W Speakers Hi-Res | H12: 2x2W Speakers Hi-Res | I12: 2x2W Speakers Hi-Res | J12: 2 x 2W Speakers Dual-array near-field microphone
A13: WLAN | B13: Wi-Fi 6E(802.11ax) | C13: Wi-Fi 6E(802.11ax) (Triple band) 2*2 | D13: Wi-Fi 6E(802.11ax) (Triple band) 2*2 | E13: Wi-Fi 6E(802.11ax) (Triple band) 2*2 | F13: Killer WiFi 7 BE1750 | G13: Killer WiFi 7 BE1750 | H13: Killer WiFi 7 BE1750 | I13: Killer WiFi 7 BE1750 | J13: Wi-Fi® 6E RZ616, 802.11ax 2x2
A14: Bluetooth | B14: 5.3 | C14: 5.2 | D14: 5.2 | E14: 5.2 | F14: 5.4 | G14: 5.4 | H14: 5.4 | I14: 5.4 | J14: 5.3
A15: Battery | B15: 50.04Wh Li-Polymer | C15: 80WHrs, 4S1P, 4-cell Li-ion | D15: 40WHrs, 4S1P, 4-cell Li-ion | E15: 40WHrs, 4S1P, 4-cell Li-ion | F15: 53Whr, 6 cell Li-ion | G15: 53Whr, 6 cell Li-ion | H15: 53Whr, 6 cell Li-ion | I15: 53Whr, 6 cell Li-ion | J15: 49.2WHr, 2-cell Super Rapid Charge( (10min charge 0~30% capacity, 30min charge 0~70% capacity, 80min charge 0~100% capacity) Controller battery capacity: 900mah
A16: Power Supply | B16: 65W Type-C AC Adapter | C16: TYPE-C, 65W AC Adapter, Output: 20V DC, 3.25A, 65W, Input: 100~240V AC 50/60Hz universal | D16: TYPE-C, 65W AC Adapter, Output: 20V DC, 3.25A, 65W, Input: 100~240V AC 50/60Hz universal | E16: TYPE-C, 65W AC Adapter, Output: 20V DC, 3.25A, 65W, Input: 100~240V AC 50/60Hz universal | F16: 65W | G16: 65W | H16: 65W | I16: 65W | J16: • 65W USB-C® (3-pin) AC adapter, supports PD 3.0, 100-240V, 50-60Hz • 65W USB-C® slim (wall-mount) AC adapter, supports PD 3.0, 100-240V, 50-60Hz
A17: Customized SW | B17: Acer Game Space | C17: YES ??? | D17: YES | E17: YES | F17: YES(MSI Center M) | G17: YES(MSI Center M) | H17: YES(MSI Center M) | I17: YES(MSI Center M)
A18: Weight | B18: 670g | C18: 678 g (1.49 lbs) | D18: 608 g | E18: 608 g | F18: 678 g (1.49 lbs) | G18: 678 g (1.49 lbs) | H18: 678 g (1.49 lbs) | I18: 678 g (1.49 lbs) | J18: 854 g (1.88 lbs)
A19: Dimensions (W x D x H) | B19: 25.6 x 11.35 x 2.25 cm | C19: 28.6 x 11.1 x 2.47 ~ 3.69 cm (11.26" x 4.37" x 0.97" ~ 1.45") | D19: 28.0 x 11.1 x 2.12 ~ 3.24 cm (11.02" x 4.37" x 0.83" ~ 1.28") | E19: 28.0 x 11.1 x 2.12 ~ 3.24 cm (11.02" x 4.37" x 0.83" ~ 1.28") | F19: 29.39 x 11.71 x 2.12 cm (11.57" x 4.61" x 0.83") | G19: 29.39 x 11.71 x 2.12 cm (11.57" x 4.61" x 0.83") | H19: 29.39 x 11.71 x 2.12 cm (11.57" x 4.61" x 0.83") | I19: 29.39 x 11.71 x 2.12 cm (11.57" x 4.61" x 0.83") | J19: 29.88 x 13.1 x 4.07 cm (11.76 x 5.16 x 1.60 inches)
A20: Xbox Game Pass | B20: PC Game Pass_3 months | C20: Xbox Game Pass Ultimate_3 months | D20: N/A | E20: N/A | F20: N/A | G20: N/A | H20: N/A | I20: N/A | J20: N/A
A21: Security | B21: Fingerprint Sensor | C21: Built-in Fingerprint Sensor Microsoft Pluton security processor | D21: Built-in Fingerprint Sensor Microsoft Pluton security processor | E21: Built-in Fingerprint Sensor Microsoft Pluton security processor | F21: N/A | G21: N/A | H21: N/A | I21: power button with TPM | J21: Firmware TPM 2.0 integrated in SoC
A22: Docking
A23: Bag
A24: Price | C24: 799.99 | D24: 649.99 | E24: 499.99 | F24: 799 | G24: 749 | H24: 699 | I24: TBD | J24: 699

Sheet LAPTOP 2026
B2: MASTER SPEC SHEET - 2026 GAMING LAPTOP PROJECTS
I4: Project Terminated | K4: Transferred to Aspire
C5: Predator Helios 18 AI | D5: Predator Helios Neo 16S AI | E5: Predator Helios Neo 16S AI | F5: Predator Helios Neo 16 AI | G5: Predator Helios Neo 16 | H5: Predator Helios Neo 18 AI | I5: Acer Nitro 16 AI | J5: Acer Nitro 16 | K5: Acer Nitro Edge 16 AI | L5: Acer Nitro Edge 16 AI | M5: Acer Nitro V 16S AI | N5: Acer Nitro V 16 AI | O5: Acer Nitro V 16 AI | P5: Acer Nitro V 16 | Q5: Acer Nitro V 16 AI | R5: Acer Nitro V 17 | S5: Acer Nitro V 15 | T5: Acer Nitro V 16
C6: ='2026 Project'!K4 -> PH18-I71 | D6: ='2026 Project'!K8 -> PHN16S-I51 | E6: ='2026 Project'!K9 -> PHN16S-I71 | F6: ='2026 Project'!K6 -> PHN16-I71 | G6: ='2026 Project'!K7 -> PHN16-I31 | H6: ='2026 Project'!K5 -> PHN18-I71 | I6: ='2026 Project'!K11 -> AN16-A71 | J6: ='2026 Project'!K10 -> AN16-A91 | K6: ='2026 Project'!#REF! -> #REF! | L6: ='2026 Project'!K12 -> ANE16-N51 | M6: ='2026 Project'!K20 -> ANV16S-I51 | N6: ='2026 Project'!K13 -> ANV16-I51 | O6: ='2026 Project'!K14 -> ANV16-A71 | P6: ='2026 Project'!K16 -> ANV16-I31 | Q6: ='2026 Project'!K15 -> ANV16-A31 | R6: ='2026 Project'!K18 -> ANV17-I31 | S6: ='2026 Project'!K19 -> ANV15-A31 | T6: ='2026 Project'!K17 -> ANV16-I11
B7: SPEC | C7: Valour_ARX | D7: FPACE_PTB | E7: FPACE_ARX | F7: MacanS_ARX | G7: MacanS_RTX | H7: iX2_ARX | I7: Mufasa_GG | J7: Mufasa_FRX | K7: Urus_PTW | L7: Urus_Ni | M7: Sorento_PTZ | N7: Picanto_PTZ | O7: Picanto_GG | P7: Picanto_RTH | Q7: Picanto_HKH | R7: Sportswagon_RTH | S7: Sportage2_RBH | T7: Delhi_RTX
B9: Unique Feature | C9: 6th Gen AeroBlade 3D Fans MegKey 4.0 6 Speakers with Predator Vox 4K Mini LED Calman Verified Dual-mode Display (4K) Thunderbolt 5 WiFi 7 | D9: Slim Copilot+ PC OLED Display Metal Chassis (A/D) Calman Verified | E9: Slim OLED Display Metal Chassis (A/D) Calman Verified | F9: OLED Display Calman Verified | H9: ACR Film (Ambient Contrast Ratio) | I9: Copilot+ PC | K9: Ultra Thin UMA Copilot+ PC OLED Display Metal Chassis (A/D) Anti-fingerprint Coating (A/D) | L9: Ultra Thin UMA OLED 2.8K Copilot+ PC (TBC) WiFi 7 Metal Chassis (A/D) | M9: Slim Copilot+ PC Camera Shutter Metal Chassis (A/D) | N9: Copilot+ PC Camera Shutter | O9: Copilot+ PC Camera Shutter | P9: Camera Shutter | Q9: Camera Shutter
B11: AI Feature | C11: Acer Intelligence Space | D11: Acer Intelligence Space | E11: Acer Intelligence Space | F11: Acer Intelligence Space | G11: Acer Intelligence Space | H11: Acer Intelligence Space | I11: Acer Intelligence Space | J11: Acer Intelligence Space | K11: Acer Intelligence Space | L11: Acer Intelligence Space | M11: Acer Intelligence Space | N11: Acer Intelligence Space | O11: Acer Intelligence Space | P11: Acer Intelligence Space | Q11: Acer Intelligence Space | R11: Acer Intelligence Space | S11: Acer Intelligence Space | T11: Acer Intelligence Space (TBC)
B13: Processor | C13: Intel Core Ultra 9 processor 290HX Plus (Arrow Lake-HX R) | D13: Intel Core Ultra 9 processor 386H Intel Core Ultra 7 processor 356H (Panthern Lake-H484) | E13: Intel Core Ultra 9 processor 290HX Plus Intel Ultra 7 processor 270HX Plus (Arrow Lake-HX R) | F13: Intel Core Ultra 9 processor 290HX Plus Intel Ultra 7 processor 270HX Plus (Arrow Lake-HX R) | G13: Intel Core i9 processor 14900HX Intel Core i7 processor 14650HX Intel Core i5 processor 14450HX (Raptor Lake-HX R) | H13: Intel Core Ultra 9 processor 290HX Plus Intel Ultra 7 processor 270HX Plus (Arrow Lake-HX R) | I13: AMD Ryzen AI 400 Series AMD Ryzen AI 7 450 (Gorgon Point) | J13: AMD Ryzen™ 9000 Series AMD Ryzen™ 9 9955HX3D processor AMD Ryzen™ 9 9955HX processor (Fire Rang) | K13: Intel Core Ultra processor H12Xe (Panther Lake) | L13: NVIDIA N1 | M13: Intel Core Ultra 7 processor 355 (Panther Lake-404) | N13: Intel Core Ultra 7 processor 355 Intel Core Ultra 5 processor 325 (Panther Lake-404) | O13: AMD Ryzen™ AI 400 Series processor AMD Ryzen™ AI 9 465 processor AMD Ryzen™ AI 7 450 processor (Gorgon Point) | P13: Intel® Core™ 9 processor 270H Intel® Core™ 7 processor 240H Intel® Core™ 5 processor 210H (Raptor Lake-H R) | Q13: AMD Ryzen 200 Series AMD Ryzen 9 270 AMD Ryzen 7 260 AMD Ryzen 5 240 (Hawk Point) | R13: Up to Intel® Core™ 9 processor 270H Intel® Core™ 7 processor 240H Intel® Core™ 5 processor 210H (Raptor Lake-H R) | S13: AMD Ryzen 100 Series AMD Ryzen 7 170 AMD Ryzen 5 150 (Rembrandt R) | T13: Intel Core i9-14900HX processor Intel Core i7-14650HX processor Intel Core i5-14450HX processor (Raptor Lake-HX R)
B14: Processor AI TOPS [up to] | C14: TBC | D14: TBC | E14: TBC | F14: TBC | G14: NA | H14: TBC | I14: TBC | J14: TBC | K14: TBC | L14: TBC | M14: TBC | N14: TBC | O14: 50 | P14: TBC | R14: NA | S14: NA | T14: TBC
B15: Processor Power | C15: TBC | D15: TBC | E15: TBC | F15: TBC | G15: TBC | H15: TBC | I15: TBC | J15: TBC | K15: TBC | L15: TBC | M15: TBC | N15: TBC | O15: 54 | P15: TBC | R15: TBC | S15: 54 | T15: TBC
B16: Intel Application Optimization [APO] | C16: Yes | D16: Yes | E16: Yes | F16: Yes | G16: Yes | H16: Yes | I16: NA | J16: NA | K16: TBC | L16: NA | M16: Yes | N16: Yes | O16: NA | P16: TBC | Q16: NA | R16: Yes | S16: NA | T16: TBC
B18: Graphic Card | C18: NVIDIA® GN22-X11/X9 NVIDIA® RTX 5090 NVIDIA® RTX 5080 VRAM: 24GB/16GB GDDR7 | D18: NVIDIA® GN22-X6/X4 NVIDIA® RTX 5070 NVIDIA® RTX 5060 VRAM: 12GB/8GB GDDR7 | E18: NVIDIA® GN22-X9/X7/X6 NVIDIA® RTX 5080 NVIDIA® RTX 5070 Ti NVIDIA® RTX 5070 VRAM: 16GB/12GB/8GB GDDR7 | F18: NVIDIA® GN22-X9/X7/X6/X4 NVIDIA® RTX 5080 NVIDIA® RTX 5070 Ti NVIDIA® RTX 5070 NVIDIA® RTX 5060 VRAM: 16GB/12GB/8GB GDDR7 | G18: NVIDIA® GN22-X6/X4/X2 NVIDIA® RTX 5070 NVIDIA® RTX 5060 NVIDIA® RTX 5050 VRAM: 12GB/8GB GDDR7 | H18: NVIDIA® GN22-X9/X7/X6/X4 NVIDIA® RTX 5080 NVIDIA® RTX 5070 Ti NVIDIA® RTX 5070 NVIDIA® RTX 5060 VRAM: 16GB/12GB/8GB GDDR7 | I18: NVIDIA® GN22-X6/X4 NVIDIA® RTX 5070 NVIDIA® RTX 5060 VRAM: 8GB GDDR7 | J18: NVIDIA® GN22-X7/X6 NVIDIA® RTX 5070 Ti NVIDIA® RTX 5070 VRAM: 12GB/8GB GDDR7 | K18: UMA Up to Intel® Core Ultra 9 Up to Intel® Core Ultra 7 Up to Intel® Core Ultra 5 w/ built-in Intel® Arc GPU | L18: UMA | M18: NVIDIA® GN22-X6/X4 NVIDIA® RTX 5070 NVIDIA® RTX 5060 VRAM: 8GB GDDR7 | N18: NVIDIA® GN22-X6/X4/X2 NVIDIA® RTX 5070 NVIDIA® RTX 5060 NVIDIA® RTX 5050 VRAM: 8GB GDDR7 | O18: NVIDIA® GN22-X6/X4/X2 NVIDIA® RTX 5070 NVIDIA® RTX 5060 NVIDIA® RTX 5050 VRAM: 8GB GDDR7 | P18: NVIDIA® GN22-X6/X4/X2 NVIDIA® RTX 5070 NVIDIA® RTX 5060 NVIDIA® RTX 5050 VRAM: 8GB GDDR7 | Q18: NVIDIA® GN22-X6/X4/X2 NVIDIA® RTX 5070 NVIDIA® RTX 5060 NVIDIA® RTX 5050 VRAM: 8GB GDDR7 | R18: NVIDIA® GN22-X6/X4/X2 NVIDIA® RTX 5070 NVIDIA® RTX 5060 NVIDIA® RTX 5050 VRAM: 8GB GDDR7 | S18: NVIDIA® GN22-X6/X4/X2 NVIDIA® RTX 5070 NVIDIA® RTX 5060 NVIDIA® RTX 5050 VRAM: 8GB GDDR7 | T18: NVIDIA® GN22-X4/X2 NVIDIA® RTX 5060 NVIDIA® RTX 5050 VRAM: 8GB GDDR7
B19: Total Graphic Power [TGP] | C19: 150w | D19: 100W | E19: 100W | F19: 150W | G19: 100W | H19: 150W | I19: TBC | J19: TBC | K19: NA | L19: NA | M19: 70W | N19: 70W | O19: 70W | P19: 60W | Q19: 70W | R19: 60W | S19: 60 W | T19: 115W
B20: Dynamic Boost | C20: 25W | D20: 15W | E20: 15W | F20: 25W | G20: 15W | H20: 25W | I20: TBC | J20: TBC | K20: NA | L20: NA | M20: 15W | N20: 15W | O20: 15W | P20: 15W | Q20: 15W | R20: 15W | S20: 15 W | T20: 25W
B21: Max Graphic Power [MGP] | C21: 175W | D21: 115W | E21: 115W | F21: 175W | G21: 115W | H21: 175W | I21: TBC | J21: TBC | K21: NA | L21: NA | M21: 85W | N21: 85W | O21: 85W | P21: 75W | Q21: 85W | R21: 75 W | S21: 75 W | T21: 140W
B22: CPU + GPU Total Design Power [TDP] | C22: 95W+175W=270W | D22: 35W+100W=135W | E22: TBC | F22: Up to 60W+150W=210W | G22: TBC | H22: TBC | I22: TBC | J22: TBC | K22: NA | L22: NA | M22: 30W+70W=100W | N22: 30W+70W=100W | O22: 30W+70W=100W | P22: 30W+70W=100W | Q22: 30W+70W=100W | R22: 35W+60W=95W | S22: 30W+60W=90W | T22: 50W+115W=165W
B23: GPU AI TOPS [up to] | C23: 1824 | D23: 798 | E23: 1334 | F23: 1334 | G23: 798 | H23: 1334 | I23: TBC | J23: 992 | K23: NA | L23: NA | M23: 798 | N23: 798 | O23: 798 | P23: 798 | Q23: 798 | R23: 798 | S23: 798 | T23: 572
B24: NVIDIA Advanced Optimus | C24: Yes | D24: Yes | E24: Yes | F24: Yes | G24: No | H24: Yes | I24: Yes | J24: Yes | K24: NA | L24: NA | M24: NA | N24: No | O24: No | P24: No | Q24: No | R24: No | S24: No | T24: No
B25: MUX Switch | C25: Yes | D25: Yes | E25: Yes | F25: Yes | G25: Yes | H25: Yes | I25: Yes | J25: Yes | K25: NA | L25: NA | M25: Yes | N25: Yes | O25: Yes | P25: Yes | Q25: Yes | R25: Yes | S25: Yes | T25: Yes
B27: Display [Panel, Resolution, Refresh Rate,Response time, Color Gamut, Brightness] | C27: Size: 18.0" Ratio: 16:10 Mini LED, WQUXGA 4K, 120Hz, 3ms, SDR mode 600 nits / HDR mode 1000 nits, DCI-P3 100%, Calman Verified, Support DUAL-MODE DISPLAY Mini LED, WQXGA 2560 x 1600, 250Hz, 3ms, SDR mode 600 nits / HDR mode 1000 nits, DCI-P3 100%, Calman Verifired | D27: Size: 16" Ratio: 16:10 OLED WQXGA 2560 x 1600, 500 nits, 165 Hz, 1ms, DCI-P3 100%, Calman Verified HDR Trueblack 1000 | E27: Size: 16" Ratio: 16:10 OLED WQXGA 2560 x 1600 240 Hz, 1ms, DCI-P3 100%, Calman Verified, HDR Trueblack 600 OLED WQXGA 2560 x 1600 165 Hz, DCI-P3 100%, 3ms | F27: Size: 16.0" Ratio: 16:10 OLED WQXGA 2560 x 1600, 165Hz, 1ms, 500 nits, DCI-P3 100%, Calman Verified WQXGA 2560 x 1600, 240Hz, 500 nits, DCI-P3 100%, 3ms WQXGA 2560 x 1600, 180Hz, 400 nits, sRGB 100%, 3ms | G27: Size: 16.0" Ratio: 16:10 WQXGA 2560 x 1600, 180Hz, 400 nits, sRGB 100%, 3ms WUXGA 1920 x 1200, 180 Hz 400 nits, sRGB 100%, 3ms | H27: Size: 18.0" Ratio: 16:10 WQXGA 2560 x 1600, 240Hz, 500 nits, DCI-P3 100%, 9ms, ACR WQXGA 2560 x 1600, 165Hz, 300 nits, sRGB 100%, 3ms | I27: 16" 16:10 WQXGA 2560 x 1600 /180Hz/400 nits/3ms/sRGB 100% WUXGA 1920 x 1200, 180 Hz | J27: 16" 16:10 WQXGA 2560 x 1600, 240Hz, 500 nits, 3ms DCI-P3 % WQXGA 2560 x 1600, 180Hz, 400 nits, 9ms, sRGB 100% | K27: 16" 16:10 OLED WQXGA+ 2880 x 1800 | L27: 16" 16:10 OLED 2.8K 120Hz WUXGA 180 Hz | M27: Size: 16.0" Ratio: 16:10 WUXGA 1920 x 1200/180Hz 9ms sRGB 100% WUXGA 1920 x 1200/120Hz 25ms sRGB 100% | N27: Size: 16.0" Ratio: 16:10 WUXGA 1920 x 1200/180Hz sRGB 100% WUXGA 1920 x 1200/165Hz NTSC 45% | O27: Size: 16.0" Ratio: 16:10 WUXGA 1920 x 1200/180Hz/3ms/sRGB 100% | P27: Size: 16.0" Ratio: 16:10 WUXGA 1920 x 1200/180Hz sRGB 100% WUXGA 1920 x 1200/120Hz sRGB 100% | Q27: Size: 16.0" Ratio: 16:10 WUXGA 1920 x 1200/180Hz sRGB 100% WUXGA 1920 x 1200/165Hz sRGB 100% | R27: Size: 17.3" Ratio: 16:9 FHD/144hz/25ms/NTSC 45%/250nits | S27: Size: 15.6" Ratio: 16:9 Full HD 1920 x 1080, 180Hz, 3ms, 300 nits, sRGB 100% Full HD 1920 x 1080, 165Hz, 300 nits, NTSC 45% | T27: Size: 16.0" Ratio: 16:10 WUXGA 1920 x 1200 165Hz 8nits 400 nits sRGB 100%
B28: Screen To Body Ratio [STB] | C28: 0.9047 | D28: 0.9087 | E28: 0.9087 | F28: 0.91 | G28: 0.91 | H28: 0.902 | I28: 0.9077 | J28: 0.9077 | K28: 0.8645 | L28: 0.8645 | M28: 0.84 | N28: 0.848 | O28: 0.848 | P28: 0.8484 | Q28: 0.848 | R28: 0.843 | S28: 0.8264
B29: G-SYNC (Level) | C29: Yes | D29: Yes | E29: Yes | F29: Yes | G29: No | H29: Yes | I29: Yes | J29: Yes | K29: No | L29: NA | M29: No | N29: No | O29: No | P29: No | Q29: No | R29: No | S29: No | T29: No
B30: FreeSync (Level) | C30: NA | D30: NA | E30: NA | F30: NA | G30: NA | H30: NA | I30: Yes | J30: Yes | K30: NA | L30: NA | M30: NA | N30: NA | O30: Yes | P30: NA | Q30: Yes | R30: NA | S30: Yes | T30: NA
B31: HDR (High Dynamic Range) | C31: Yes | D31: Yes | E31: Yes | F31: Yes | G31: No | H31: No | I31: No | J31: No | K31: Yes | L31: Yes | M31: No | N31: No | O31: No | P31: No | Q31: No | R31: No | S31: No | T31: No
B33: Thermal Solution
B34: Cooling Fan Material & Qty | C34: 6th Gen AeroBlade Metal Fan*2 | D34: 5th Gen AeroBlade Metal Fan*1 Plastic Fan*1 | E34: 5th Gen AeroBlade Metal Fan*1 Plastic Fan*1 | F34: 5th Gen AeroBlade Metal Fan*1 Plastic Fan*1 | G34: 5th Gen AeroBlade Metal Fan*1 Plastic Fan*1 | H34: 5th Gen AeroBlade Metal Fan*1 Plastic Fan*1 | I34: Plastic Fan*2 Dual-fan quad-intake quad-exhaust | J34: Plastic Fan*2 Dual-fan quad-intake quad-exhaust | K34: Plastic Fan*2 Dual-fan dual-intake dual-exhaust | L34: Plastic Fan*2 Dual-fan dual-intake dual-exhaust | M34: Plastic Fan*2 Dual-fan dual-intake dual-exhaust | N34: Plastic Fan*2 Dual-fan dual-intake dual-exhaust | O34: Plastic Fan*2 Dual-fan dual-intake dual-exhaust | P34: Plastic Fan*2 Dual-fan dual-intake dual-exhaust | Q34: Plastic Fan*2 Dual-fan dual-intake dual-exhaust | R34: Plastic Fan*2 Dual-fan dual-intake dual-exhaust | S34: Plastic Fan*2 Dual-fan dual-intake dual-exhaust | T34: Plastic Fan*2 Dual-fan dual-intake dual-exhaust
B35: Liquid Metal Thermal Grease | C35: Yes | D35: Yes | E35: Yes | F35: Yes | G35: No | H35: Yes | I35: Yes | J35: No | K35: No | L35: No | M35: No | N35: No | O35: No | P35: No | Q35: No | R35: No | S35: No | T35: No
B36: Vector Heat Pipes | C36: Yes | D36: No | E36: No | F36: Yes | G36: Yes | H36: Yes | I36: Yes | J36: Yes | K36: No | L36: No | M36: No | N36: No | O36: No | P36: No | Q36: No | R36: No | S36: No | T36: No
B37: Vortex Flow | C37: No | D37: No | E37: No | F37: No | G37: No | H37: No | I37: No | J37: No | K37: Yes | L37: Yes | M37: No | N37: No | O37: No | P37: No | Q37: No | R37: No | S37: No | T37: No
B38: Vapor Chamber | C38: No | D38: No | E38: No | F38: No | G38: No | H38: No | I38: No | J38: No | K38: No | L38: No | M38: No | N38: No | O38: No | P38: No | Q38: No | R38: No | S38: No | T38: No
B40: Memory | C40: Up to 256 GB DDR5 4000 MT/s (TBC) (64GB x4 CSO-DIMM) | D40: Up to 64 GB DDR5 6400 MT/s | E40: Up to 64 GB DDR5 6400 MT/s (TBD) | F40: Up to 64GB DDR5 6400 MT/s | G40: Up to 32 GB DDR5 5600 MT/s | H40: Up to 64 GB (TBC) DDR5 6400 MT/s | I40: Up to 32 GB DDR5 5600 MT/s | J40: Up to 32 GB DDR5 5600 MT/s | K40: Up to 32GB LPDDR5X | L40: Up to 32 GB LPDDR5X | M40: Up to 32 GB DDR5 5600 MT/s | N40: Up to 32 GB DDR5 5600 MT/s | O40: Up to 32 GB DDR5 5600 MT/s SO-DIMM*2 | P40: Up to 32 GB DDR5 5600 MT/s | Q40: Up to 32 GB DDR5 5600 MT/s SO-DIMM*2 | R40: Up to 32 GB DDR5 5600 MT/s SO-DIMM*2 | S40: Up to 32 GB DDR5 4800 MT/s SO-DIMM*2 | T40: Up to 32 GB DDR5 5600 MT/s
B41: Storage | C41: Up to 6 TB PCIe M.2 SSD Up to Gen 5*3 (HDD1-Gen5 PMP5 HDD2/HDD3 - Gen4 PM4) | D41: Up to 2 TB PCIe M.2 NVMe SSD Gen 4*2 | E41: Up to 2 TB PCIe M.2 SSD Gen 4*2 | F41: Up to 2 TB PCIe M.2 SSD Gen 4*2 or PCIe M.2 Gen 4 SSD SSD slot: 2 Up to 2 TB | G41: Up to 2 TB PCIe M.2 NVMe SSD Gen 4*2 | H41: Up to 2 TB PCIe M.2 SSD Gen 4*2 | I41: Up to 2 TB PCIe M.2 SSD Gen 4*2 | J41: Up to 2 TB PCIe M.2 SSD Gen 4*2 | K41: Up to 2 TB PCIe M.2 SSD Gen 5*1 (TBD) + Gen 4*1 | L41: Up to 2 TB PCIe M.2 SSD Gen 4*2 | M41: Up to 2 TB PCIe M.2 SSD Gen 4*2 | N41: Up to 2 TB PCIe M.2 SSD Gen 4*2 | O41: Up to 2 TB PCIe M.2 SSD Gen 4*2 | P41: Up to 2 TB PCIe M.2 SSD Gen 4*2 | Q41: Up to 2 TB PCIe M.2 SSD Gen 4*2 | R41: Up to 1 TB PCIe M.2 SSD Gen 4*2 | S41: Up to 1 TB PCIe M.2 NVMe SSD Gen 4*1 | T41: Up to 2 TB PCIe M.2 SSD Gen 4*2
B43: Wi-FI | C43: Kiler 1750x Wi-Fi 7 | D43: Killer Wi-Fi 6E 1675i | E43: Killer Wi-Fi 6E 1675i | F43: Killer Wi-Fi 6E 1675i | G43: Killer Wi-Fi 6E 1675i | H43: Killer Wi-Fi 6E 1675i | I43: Wi-Fi 6E RZ616:E | J43: Wi-Fi 6E RZ616:E | K43: Killer Wi-Fi 6E 1675i | L43: WiFi 7 M&7925 | M43: Killer Wi-Fi 6E | N43: Killer Wi-Fi 6E 1675i / AX211 | O43: Wi-Fi 6E | P43: Killer Wi-Fi 6 1650i | Q43: Wi-Fi 6E | R43: Wi-Fi 6 | S43: Wi-Fi 6E | T43: Wi-Fi 6E AX211
B44: Bluetooth | C44: 5.4 or above | D44: 5.3 or above | E44: 5.4 or above | F44: 5.4 or above | G44: 5.4 or above | H44: 5.3 or above | I44: 5.3+ | J44: 5.3+ | K44: 5.3+ | L44: 5.4 | M44: 5.2 | N44: 5.3 | O44: 5.4 | P44: 5.2 | Q44: 5.4 | R44: 5.4 or above | S44: 5.4 or above | T44: 5.2
B45: LAN | C45: Killer™ Ethernet E5000B | D45: Killer™ Ethernet E3100G | E45: Killer™ Ethernet E3100G | F45: Killer™ Ethernet E3100G | G45: Killer™ Ethernet E3100G | H45: Killer™ Ethernet E3100G | I45: Killer™ Ethernet E3100G | J45: Killer™ Ethernet E3100G | K45: Killer™ Ethernet E3100G | L45: Realtek RTL8125BGS-CG | M45: Killer™ Ethernet E2600 | N45: Killer™ Ethernet E2600 | O45: Killer™ Ethernet E2600 | P45: Killer™ Ethernet E2600 | Q45: Killer™ Ethernet E2600 | R45: Killer™ Ethernet E2600 | S45: Killer™ Ethernet E2600 | T45: Supports 10/100/1000 Mb/sec
B46: Battery [W] | C46: 99 Wh | D46: 92 Wh | E46: 92 Wh | F46: 92 Wh | G46: 92 Wh | H46: 92Wh | I46: 92 Wh | J46: 92 Wh | K46: 84 Wh | L46: 84 Wh | M46: 76 Wh | N46: 76 Wh | O46: 76 Wh | P46: 76 Wh | Q46: 76 Wh | R46: 76 Wh | S46: 76 Wh | T46: 53 Wh
B47: AC Power Adapter | C47: 400W | D47: 230W | E47: 230W | F47: 330W | G47: 330W | H47: 330W | I47: 230W | J47: 330W | K47: 100W via Type C | L47: 100W via Type C | M47: 180W | N47: 180W | O47: 180W | P47: 135W | Q47: 180W | R47: 135W | S47: 135W | T47: 180W
B48: I/O Ports | C48: TypeC Thunderbolt™ 5*2 Type A USB 3.2 Gen 1*1 USB 3.2 Gen 2*1 (one with offline charging) USB 3.2 Gen 1*1 HDMI 2.1*1 SD™ Card reader*1 3.5mm Combo Audio Jack*1 RJ-45*1 DC-In*1 K-lock*1 | D48: TypeC Thunderbolt™ 4*1 USB 3.2 Gen 2*1 (Full Function) Type A USB 3.2 Gen 2*2 (one with offline charging) USB 3.2 Gen 1*1 HDMI 2.1*1 microSD™ Card reader*1 3.5mm Combo Audio Jack*1 RJ-45*1 DC-In *1 | E48: TypeC Thunderbolt™ 4*1 USB 3.2 Gen 2*1 (Full Function) Type A USB 3.2 Gen 2*2 (one with offline charging) USB 3.2 Gen 1*1 HDMI 2.1*1 microSD™ Card reader*1 3.5mm Combo Audio Jack*1 RJ-45*1 DC-In *1 | F48: TypeC Thunderbolt™ 4*1 USB 3.2 Gen 2*1 (Full Function) Type A USB 3.2 Gen 2*2 (one with offline charging) USB 3.2 Gen 1*1 HDMI 2.1*1 microSD™ Card reader*1 3.5mm Combo Audio Jack*1 RJ-45*1 DC-In*1 K-lock*1 | G48: TypeC Thunderbolt™ 4*2 Type A USB 3.2 Gen 2*2 (one with offline charging) USB 3.2 Gen 1*1 HDMI 2.1*1 microSD™ Card reader*1 3.5mm Combo Audio Jack*1 RJ-45*1 DC-In*1 K-lock*1 | H48: TypeC Thunderbolt™ 4*1 USB 3.2 Gen 2 Full Function*1 Type A USB 3.2 Gen 2*2 (one with offline charging) USB 3.2 Gen 1*1 HDMI 2.1*1 microSD™ Card reader*1 3.5mm Combo Audio Jack*1 RJ-45*1 DC-In*1 K-lock*1 | I48: Type C USB4*1 (Full Function) Type A USB3.2 Gen2*2 (one with offline charging) USB2.0*1 HDMI 2.1*1 Micro SD card*1 Audio Jack*1 RJ45*1 K-lock*1 DC-In x 1 | J48: Type C USB4*1 (Full Function) Type A USB3.2 Gen2*2 (one with offline charging) USB2.0*1 HDMI 2.1*1 Micro SD card*1 Audio Jack*1 RJ45*1 K-lock*1 DC-In x 1 | K48: Type C Thunderbolt™ 4*2 (with PD) Type A USB3.2 Gen 2*1 (offline charging) USB3.2 Gen1*1 HDMI 2.1*1 MicroSD 3.0*1 Combo Jack*1 RJ45*1 | L48: Type C USB 3.2 Gen 2*2 (Full Function) Type A USB3.2 Gen 2*1 (offline charging) USB3.2 Gen1*1 HDMI 2.1*1 MicroSD 3.0 card*1 Combo Jack*1 RJ45*1 | M48: TypeC Thunderbolt™ 4*1 (with PD) Type A USB 3.2 Gen 2*1 (offline charging) USB 3.2 Gen 1*2 HDMI 2.1*1 3.5mm Combo Audio Jack*1 RJ-45*1 DC-In*1 K-lock*1 | N48: TypeC Thunderbolt™ 4*1 (with DP3.0) Type A USB 3.2 Gen 2*1 (offline charging) USB 3.2 Gen 1*2 HDMI 2.1*1 3.5mm Combo Audio Jack*1 RJ-45*1 DC-In*1 K-lock*1 | O48: TypeC USB4*1 (Full function) Type A USB 3.2 Gen 2*1 (offline charging) USB 3.2 Gen 1*2 HDMI 2.1*1 3.5mm Combo Audio Jack*1 RJ-45*1 DC-In*1 K-lock*1 | P48: TypeC Thunderbolt™ 4*1 (USB+PD+DP1.4) Type A USB 3.2 Gen 2*1 (offline charging) USB 3.2 Gen 1*2 HDMI 2.1*1 3.5mm Combo Audio Jack*1 RJ-45*1 DC-In*1 K-lock*1 | Q48: TypeC USB4*1 (Full function) Type A USB 3.2 Gen 2*1 (offline charging) USB 3.2 Gen 1*2 HDMI 2.1*1 3.5mm Combo Audio Jack*1 RJ-45*1 DC-In*1 K-lock*1 | R48: TypeC Thunderbolt 4*1 Type A USB3.2 Gen1 Gen 1*3 (one with offline charging) HDMI x 1 RJ45 x 1 Audio jack (combo) x 1 Realtek ALC245 DC-In x 1 K-lock x 1 | S48: TypeC USB4*1 40Gbps Type A USB3.2 Gen1*3 (one with offline charger) HDMI x 1 RJ45 x 1 Audio jack (combo) x 1 Realtek ALC245 DC-In x 1 K-lock x 1 | T48: TypeC USB 3.2 Gen2 Type C*2 Type A USB 3.2 Gen 2*1 (offline charging) USB 3.2 Gen 1*1 HDMI 2.1*1 3.5mm Combo Audio Jack*1 RJ-45*1 DC-In*1 K-lock*1
B49: Touchpad | C49: Yes | D49: Yes | E49: Yes | F49: Yes | G49: Yes | H49: Yes | I49: Yes | J49: Yes | K49: Yes | L49: Yes | M49: Yes | N49: Yes | O49: Yes | P49: Yes | Q49: Yes | R49: Yes | S49: Yes | T49: Yes
B50: Keyboard | C50: Per-Key RGB | D50: 4-Zone RGB | E50: 4-Zone RGB | F50: 4-Zone RGB | G50: 4-Zone RGB | H50: 4-Zone RGB | I50: 4-Zone RGB | J50: 4-Zone RGB | K50: 4-Zone RGB | L50: 4-Zone RGB | M50: 4-Zone RGB | N50: 4-Zone RGB | O50: 4-Zone RGB | P50: 4-Zone RGB | Q50: 4-Zone RGB | R50: 4-Zone RGB | S50: 4-Zone RGB | T50: 4-Zone RGB
...

Sheet DEKSTOP 2026
B2: MASTER SPEC SHEET - 2025 GAMING DESKTOP PROJECTS
B5: Marketing Name | C5: PREDATOR ORION 7000 | D5: PREDATOR ORION 3000 | E5: PREDATOR ORION NEO | F5: Acer Nitro 30 (AMD) | G5: Acer Nitro 30 (Intel) | H5: Acer Nitro 20 | I5: Acer Nitro 10 | J5: Acer Nitro 20 | K5: Acer Nitro 10
B6: Model Name | C6: PO7-667_Z890 | D6: PO3-667 (H810/H610) | E6: PON-100-ARLHX PON-100-RPLHX | F6: N30-101 (B850/A520) | G6: N30-101 (H810/H610) | H6: N20-101-MTL | I6: N10-101-MTL | J6: N20-110-ARLHX N20-110-RPLHX | K6: N10-110-ARLHX N10-110-RPLHX
B7: Project Name | C7: Agera | D7: PO3-665 | E7: ArteonRW | F7: PO3-665 | G7: PO3-665 | H7: TC102 | I7: XC102 | J7: vAnzioHX vAnconaHX | K7: vAnzioHX vAnconaHX
B9: Unique Feature | C9: Predator CycloneX 360 Predator CycloneX 360 + CPU Liquid Cooling
B11: AI Feature | C11: Acer Intelligence Space | D11: Acer Intelligence Space | E11: Acer Intelligence Space | F11: Acer Intelligence Space | G11: Acer Intelligence Space | H11: NA | I11: NA | J11: NA | K11: NA
B13: Processor | C13: Intel® Core Ultra 7 processor 270K Plus (Arrow Lake-S Refresh) | D13: Intel® Core Ultra 7 processor 265F Intel® Core™ Ultra 5 processor 225F | E13: Intel® Core Ultra 9 processor 290HX Plus Intel® Core™ Ultra 7 processor 270HX Plus Intel® Core™ i9-14900HX processor Intel® Core™ i7-14700HX processor | F13: AMD Ryzen 7 8700G AMD Ryzen 5 8500G AMD Ryzen 7 7700 AMD Ryzen 5 5600G | G13: Intel® Core Ultra 7 processor 265F Intel® Core™ Ultra 5 processor 225F | H13: Intel Core Ultra 5 processor 125H (Meteor Lake) | I13: Intel Core Ultra 5 processor 125H (Meteor Lake) | J13: Up to Intel Core Ultra 7 270HX Plus (Arrow Lake-HX R) Up to Intel Core i7-14700HX (Raptor Lake-HX R) | K13: Up to Intel Core Ultra 7 270HX Plus (Arrow Lake-HX R) Up to Intel Core i7-14700HX (Raptor Lake-HX R)
B14: MB Chipset | C14: Intel® Z890 Chipset
B15: Processor Power (range) | C15: U9K: 125W U7KF: 125W | D15: U7F: 65W U5F: 65W | E15: U7F: 65W U5F: 65W | F15: 65W | G15: U7F: 65W U5F: 65W | H15: 45W | I15: 45W | J15: 45W | K15: 45W
B16: Processor AI TOPS [up to] | D16: CPU: 13.6 TOPs NPU: 13.1 TOPs | G16: CPU: 13.6 TOPs NPU: 13.1 TOPs
B17: Intel Application Optimization [APO] | C17: No | D17: No | E17: No | F17: No | G17: No | H17: No | I17: No | J17: No | K17: No
B19: Graphics Card | C19: NVIDIA® GeForce RTX™ 5090 32 GB NVIDIA® GeForce RTX™ 5080 16 GB NVIDIA® GeForce RTX™ 5070 12 GB | D19: NVIDIA® GeForce RTX™ 5070 12 GB | E19: NVIDIA® GeForce RTX™ 5080 | F19: AMD Radeon™ RX 9070 XT 16GB (KSP claim) AMD Radeon™ RX 9060 XT NVIDIA® GeForce RTX™ 5070 12 GB | G19: NVIDIA® GeForce RTX™ 5070 12 GB (KSP claim) Up to AMD Radeon™ RX 9070 XT 16GB AMD Radeon™ RX 9060 XT | H19: Up to NVIDIA® GeForce RTX™ 5060 8 GB | I19: Intel Arc A380 | J19: Up to NVIDIA® GeForce RTX™ 5060 8 GB | K19: Intel Arc A380
B20: Graphics Card Power Max Graphic Power [MGP] | C20: RTX 5090: 575W RTX 5080: 360W RTX 5070: 250W | H20: RTX 5060: 145W | I20: 75W | J20: RTX 5060: 145W | K20: 75W
B21: GPU AI TOPS [up to] | C21: RTX 5090: 3352 TOPS RTX 5080: 1801 TOPS RTX 5070: 988 TOPS
B23: CPU Cooling | C23: CycloneX 360 [ARGB] + Liquid Cooling [ARGB] | D23: 65W air cooler ARGB Lighting | E23: 65W air cooler ARGB Lighting | F23: 65W air cooler ARGB Lighting | G23: 65W air cooler ARGB Lighting | H23: AIR Cooling (80mm Fan) | I23: AIR Cooling (80mm Fan) | J23: AIR Cooling (80mm Fan) | K23: AIR Cooling (80mm Fan)
B24: Graphic Card Cooling | C24: GPU Fan [default]
B25: System Cooling | C25: Front: CycloneX 360 x 1 [ARGB] Rear: System fan | D25: Two 120mm system fans (front & rear) ARGB Lighting | E25: Four 120mm system fans (3 front & 1 rear) ARGB Lighting | F25: Two 120mm system fans (front & rear) ARGB Lighting | G25: Two 120mm system fans (front & rear) ARGB Lighting | H25: N/A | I25: N/A | J25: N/A | K25: N/A
B27: Memory | C27: Up to 128 GB DDR5 XMP RGB | D27: 16/8 GB DDR5 5600 MT/s UDIMM Up to 64 GB of Dual-channel DDR5 5600 MT/s | E27: Up to 32 GB DDR5 5600 MT/s; supports up to 7200 MT/s via XMP | F27: 16/8 GB DDR5 5600 MT/s UDIMM Up to 64 GB of Dual-channel DDR5 5600 MT/s | G27: 16/8 GB DDR5 5600 MT/s UDIMM Up to 64 GB of Dual-channel DDR5 5600 MT/s | H27: Up to 32GB of Dual-channel DDR5 5600 MT/s | I27: Up to 32GB of Dual-channel DDR5 5600 MT/s (SODIMM*2) | J27: Up to 32GB of Dual-channel DDR5 5600 MT/s | K27: Up to 32GB of Dual-channel DDR5 5600 MT/s (SODIMM*2)
B28: Memory slot | C28: 4 | D28: 2 | E28: 2 | F28: 2 | G28: 2 | H28: SODIMM*2 | I28: SODIMM*2 | J28: SODIMM*2 | K28: SODIMM*2
B29: SSD | C29: Up to 6TB SSD storage PCIe Gen 5 NVMe M.2 SSD x 1 PCIe Gen 4 NVMe M.2 SSD x 2 | D29: Up to 2TB NVMe M.2 2280 PCIe SSD PCIe Gen 4 x 2 | E29: Up to 2 TB PCI-e Gen 5 SSD (ARL) Up to 2 TB PCI-e Gen 4 SSD (RPL) | F29: Up to 2TB NVMe M.2 2280 PCIe SSD PCIe Gen 4 x 2 | G29: Up to 2TB NVMe M.2 2280 PCIe SSD PCIe Gen 4 x 2 | H29: Up to 1TB M.2 PCI-e Gen4 SSD | I29: Up to 1TB M.2 PCI-e Gen4 SSD | J29: Up to 1TB M.2 PCI-e Gen4 SSD | K29: Up to 1TB M.2 PCI-e Gen4 SSD
B30: HDD | C30: Up to 4 TB HDD storage 3.5” HDD x 2 | D30: Up to 2 TB 7200 RPM HDD 3.5-inch x 1 | E30: Up to 2 TB 7200 RPM HDD | F30: Up to 2 TB 7200 RPM HDD 3.5-inch x 1 | G30: Up to 2 TB 7200 RPM HDD 3.5-inch x 1 | H30: Up to 1TB 3.5" HDD | I30: Up to 1TB 3.5" HDD | J30: Up to 1TB 3.5" HDD | K30: Up to 1TB 3.5" HDD
B32: LAN | C32: Killer™ Ethernet E3100G | D32: Realtek 8111H Ethernet | E32: 2.5G Giga LAN | F32: Realtek 8111H Ethernet | G32: Realtek 8111H Ethernet | H32: Realtek RTL8111H Gigabit Ethernet | I32: Realtek RTL8111H Gigabit Ethernet | J32: Realtek RTL8111H Gigabit Ethernet | K32: Realtek RTL8111H Gigabit Ethernet
B33: Wireless LAN | C33: Wi-Fi 7/6E | D33: Wi-Fi 7/6E | E33: WiFi 7 (ARL) WiFi 6E (RPL) | F33: Wi-Fi 7/6E | G33: Wi-Fi 7/6E | H33: Up to WiFi 6E | I33: Up to WiFi 6E | J33: Up to WiFi 7/WiFi 6E | K33: Up to WiFi 7/WiFi 6E
B34: Bluetooth | C34: 5 | D34: 5 | E34: 5 | F34: 5 | G34: 5 | H34: 5.2 | I34: 5.2 | J34: 5.2 | K34: 5.2
B36: AC Power Adapter | C36: 1000W | D36: 850 W PFC, auto-sensing, 80PLUS® Gold, TFX | E36: Up to 850/600 W | F36: 850 W PFC, auto-sensing, 80PLUS® Gold, TFX | G36: 850 W PFC, auto-sensing, 80PLUS® Gold, TFX | H36: 400W | I36: 180 W | J36: 400W | K36: 180 W
B37: I/O Ports | C37: Front/Front I/O connectors • USB 3.2 Gen1 5Gbps Type A port(s): 2 • USB 3.2 Gen1 5Gbps Type C port(s): 1 Audio jack(s): 1 (headphone + mic, mic) Rear I/O connectors • LAN port(s): 1 • Audio jack(s): 3 [line in, audio out, mic] • USB 2.0 Type A port(s): 2 • USB 3.2 Gen2 10Gbps Type A port(s): 3 • Thunderbolt 4: 1 | D37: Front/Side I/O connectors • Audio jack(s): 1 (headphone + mic, mic) • USB 3.2 Gen2 10Gbps Type A port(s): 2 • USB 3.2 Gen2x2 20Gbps Type C port(s): 1 Rear I/O connectors • LAN port(s): 1 • Audio jack(s): 3 [line in, audio out, mic] • USB 2.0 Type A port(s): 4 • USB 3.2 Gen1 5Gbps Type A port(s): 2 | E37: Front/Side I/O connectors • Audio jack(s): 1 (headphone + mic, mic) • USB 3.2 Gen2 10Gbps Type A port(s): 2 • USB 3.2 Gen2x2 20Gbps Type C port(s): 1 Rear I/O connectors • LAN port(s): 1 • Audio jack(s): 3 [line in, audio out, mic] • USB 2.0 Type A port(s): 4 • USB 3.2 Gen1 5Gbps Type A port(s): 2 | F37: Front/Side I/O connectors • Audio jack(s): 1 (headphone + mic, mic) • USB 3.2 Gen2 10Gbps Type A port(s): 2 • USB 3.2 Gen2x2 20Gbps Type C port(s): 1 Rear I/O connectors • LAN port(s): 1 • Audio jack(s): 3 [line in, audio out, mic] • USB 2.0 Type A port(s): 4 • USB 3.2 Gen1 5Gbps Type A port(s): 2 | G37: Front/Side I/O connectors • Audio jack(s): 1 (headphone + mic, mic) • USB 3.2 Gen2 10Gbps Type A port(s): 2 • USB 3.2 Gen2x2 20Gbps Type C port(s): 1 Rear I/O connectors • LAN port(s): 1 • Audio jack(s): 3 [line in, audio out, mic] • USB 2.0 Type A port(s): 4 • USB 3.2 Gen1 5Gbps Type A port(s): 2 | H37: Front/Side I/O connectors • Card reader: N • Audio jack(s): 1 • USB 2.0 Type A port(s): 2 • USB 3.2 Gen1 5Gbps Type A port(s): 2 • USB 3.2 Gen1 5Gbps Type C port(s): 1 Rear I/O connectors • D-Sub port(s): 1 • HDMI port(s): 1 • DP port(s): 1 • LAN port(s): 2 • Audio jack(s): 2 • USB 2.0 Type A port(s): 2 • USB 3.2 Gen2 10Gbps Type A port(s): 2 | I37: Front/Side I/O connectors • Card reader: N • Audio jack(s): 1 • USB 2.0 Type A port(s): 2 • USB 3.2 Gen1 5Gbps Type A port(s): 2 • USB 3.2 Gen1 5Gbps Type C port(s): 1 Rear I/O connectors • D-Sub port(s): 1 • HDMI port(s): 1 • DP port(s): 1 • LAN port(s): 2 • Audio jack(s): 2 • USB 2.0 Type A port(s): 2 • USB 3.2 Gen2 10Gbps Type A port(s): 2 | J37: Front/Side I/O connectors • Card reader: N • Audio jack(s): 1 • USB 2.0 Type A port(s): 2 • USB 3.2 Gen1 5Gbps Type A port(s): 2 • USB 3.2 Gen1 5Gbps Type C port(s): 1 Rear I/O connectors • D-Sub port(s): 1 • HDMI port(s): 1 • DP port(s): 1 • LAN port(s): 2 • Audio jack(s): 2 • USB 2.0 Type A port(s): 2 • USB 3.2 Gen2 10Gbps Type A port(s): 2 | K37: Front/Side I/O connectors • Card reader: N • Audio jack(s): 1 • USB 2.0 Type A port(s): 2 • USB 3.2 Gen1 5Gbps Type A port(s): 2 • USB 3.2 Gen1 5Gbps Type C port(s): 1 Rear I/O connectors • D-Sub port(s): 1 • HDMI port(s): 1 • DP port(s): 1 • LAN port(s): 2 • Audio jack(s): 2 • USB 2.0 Type A port(s): 2 • USB 3.2 Gen2 10Gbps Type A port(s): 2
B38: Hot Swap | C38: N/A | D38: N/A | E38: N/A | F38: N/A | G38: N/A | H38: N/A | I38: N/A | J38: N/A | K38: N/A
B39: I/O expansions | C39: PCIe Gen 5 x16 slot: 1 PCIe M.2 WLAN slot: 1 PCIe Gen 5 x4 M.2 SSD slot: 1 PCIe Gen 4 x4 M.2 SSD slot: 2 | D39: • PCIe x16 slot(s): 1 • M.2 slot (for SSD): 2 • M.2 slot (for WLAN): 1 | F39: • PCIe x16 slot(s): 1 • M.2 slot (for SSD): 2 • M.2 slot (for WLAN): 1 | G39: • PCIe x16 slot(s): 1 • M.2 slot (for SSD): 2 • M.2 slot (for WLAN): 1 | H39: •PCIe x16 slot(s): 1 • PCIe x1 slot(s): 1 • M.2 slot (for SSD): 1 • M.2 slot (for WLAN): 1 | I39: •PCIe x16 slot(s): 1 • PCIe x1 slot(s): 1 • M.2 slot (for SSD): 1 • M.2 slot (for WLAN): 1 | J39: •PCIe x16 slot(s): 1 • PCIe x1 slot(s): 1 • M.2 slot (for SSD): 1 • M.2 slot (for WLAN): 1 | K39: •PCIe x16 slot(s): 1 • PCIe x1 slot(s): 1 • M.2 slot (for SSD): 1 • M.2 slot (for WLAN): 1
B40: SATA | C40: 2 x 3.5” SATA3 6.0Gb/s HDD connector | D40: 1 x 3.5” SATA3 HDD M.2 SSD/2280/2242 | F40: 1 x 3.5” SATA3 HDD M.2 SSD/2280/2242 | G40: 1 x 3.5” SATA3 HDD M.2 SSD/2280/2242
B41: Audio | C41: DTS:X® Ultra | D41: DTS:X® Ultra | E41: DTS:X® Ultra | F41: DTS:X® Ultra | G41: DTS:X® Ultra | H41: Integrated high-definition sound | I41: Integrated high-definition sound | J41: Integrated high-definition sound | K41: Integrated high-definition sound
B42: OS | C42: Windows 11 Home 64-bit. UEFI Shell | D42: Windows 11 Home 64-bit. UEFI Shell | E42: Windows 11 Home 64-bit. UEFI Shell | F42: Windows 11 Home 64-bit. UEFI Shell | G42: Windows 11 Home 64-bit. UEFI Shell | H42: Windows 11 Home 64-bit. UEFI Shell | I42: Windows 11 Home 64-bit. UEFI Shell | J42: Windows 11 Home 64-bit. UEFI Shell | K42: Windows 11 Home 64-bit. UEFI Shell
B43: Sense | C43: AcerSense Pro | D43: AcerSense Pro | E43: AcerSense Pro | F43: AcerSense Pro | G43: AcerSense Pro | H43: AcerSense Pro | I43: AcerSense Pro | J43: AcerSense Pro | K43: AcerSense Pro
B44: Acer Intellengence Space | C44: Yes | D44: Yes | E44: Yes | F44: Yes | G44: Yes | H44: Yes | I44: Yes | J44: Yes | K44: Yes
B46: Material [PCR %] | C46: 0.65 | H46: N/A | I46: N/A | J46: N/A | K46: N/A
B47: Dimension [W*D*H] | C47: 216.4 (W) x 461.7 (D) x 495.4 (H) mm | H47: 160 (W) x 306 (D) x 348 (H) mm | I47: 100 (W) x 295 (D) x 330 (H) mm
B48: Weight | C48: TBD | D48: 12 kg | E48: 12 kg | F48: 12 kg | G48: 12 kg
B49: Volume (L) | C49: 45L | D49: 32L | E49: 32L | F49: 32L | G49: 32L | H49: 15L | I49: 9L | J49: 17.3 L | K49: 7.6 L
B53: FCS | C53: 46115 | D53: 45747 | E53: 45762 | F53: 2/E/2026 | G53: 2/E/2026 | H53: 3/B/2026 | I53: 3/B/2026 | J53: 6/30/2026 3/31/2026 | K53: 6/30/2026 3/31/2026
B55: PM | C55: James L | D55: James L | E55: Hour Tsai | F55: James L | G55: James L | H55: Hour Tsai | I55: Hour Tsai | J55: Hank PH Chen | K55: Hank PH Chen
B57: KSP Bullets | C57: Intel® Core Ultra 7 processor 270K Plus | D57: Intel® Core Ultra 7 processor 265F | E57: Intel® Core Ultra 9 processor 290HX Plus | F57: Up to AMD Ryzen 7 8700G Processor | G57: Up to Intel® Core Ultra 7 processor 265F | H57: Up to Intel® Core™ Ultra 5 processor 125H | I57: Up to Intel® Core™ Ultra 5 processor 125H | J57: Up to Intel® Core™ Ultra 7 processor 270HX Plus | K57: Up to Intel® Core™ Ultra 7 processor 270HX Plus
...

Sheet HANDHELD 2026
B2: 2026 GAMING HANDHELD. PROJECTS
C5: PREDATOR ATLAS 7 | D5: PREDATOR ATLAS 8 | E5: ROG/MSI/Legion Go
E6: Reference Specs
B7: SPEC | C7: G310_PTG | D7: F900_PTG
B9: Unique Feature | C9: The metal fan performs 10% better than the plastic fan. Plastic fan: 0.3mm thickness, 73 blades Metal fan: 0.1mm thickness, 89 blades | D9: The metal fan performs 10% better than the plastic fan. Plastic fan: 0.3mm thickness, 73 blades Metal fan: 0.1mm thickness, 89 blades
B11: AI Feature
B13: Processor | C13: Intel® Arc™ G3 Extreme processor Intel® Arc™ G3 processor | D13: Intel® Arc™ G3 Extreme processor Intel® Arc™ G3 processor | E13: Up to Intel® Core™ Ultra 7 processor(Series 2)
B14: Processor AI TOPS [up to] | C14: > 40TOPS int8 | D14: > 40TOPS int8 | E14: Up to 47 NPU TOPS (119 total AI TOPS)
B15: Graphics | C15: UMA | D15: UMA | E15: Up to Intel® Arc™ 140V GPU
B16: Display [Panel, Resolution, Refresh Rate, 亮度, 色域, Response time] | C16: 7-inch FHD (1920 x 1080) 16:9 IPS-level Glossy display sRGB: 100% Adobe: 75.35% Gorilla Glass Victus Gorilla Glass DXC Touch Screen Refresh Rate: 120Hz Brightness: 500 nits | D16: 8-inch FHD+ (1920 x 1200) 16:10 IPS-level sRGB: 100% Adobe: ?% Gorilla® Glass Victus™ Gorilla® Glass DXC Touch Screen (10-point multi-touch) Refresh Rate: 120Hz Brightness: 500 nits | E16: 7-inch FHD (1920 x 1080) 16:9 IPS-level Glossy display sRGB: 100% Adobe: 75.35% Gorilla® Glass Victus™ Gorilla® Glass DXC Touch Screen (10-point multi-touch) Refresh Rate: 120Hz Brightness: 500 nits
B17: FreeSync (Level) | C17: N/A | D17: N/A | E17: AMD FreeSync™ Premium (Variable Refresh Rate)
B18: Thermal Solution | C18: dual FAN (Aero Blade metal + plastic) vortex flow | D18: Dual Fan [Predator AeroBlade Metal Fan *1 + Plastic Fan *1] Vortex flow | E18: TBD
B19: Cooling Fan Material & Qty | C19: Predator AeroBlade Fan*1 Plastic Fan*1 | D19: Predator AeroBlade Metal Fan *1 Plastic Fan *1 | E19: 5th Gen AeroBlade 3D Fan*2
B20: Liquid Metal Thermal Grease | C20: No | D20: No | E20: NO
B21: Vortex Flow | C21: Yes | D21: Yes | E21: NO
B23: Memory | C23: LPDDR5x, 16GB, 7467MT/s or 8533MT/s [TBD] LPDDR5x, 24GB, 7467MT/s or 8533MT/s [TBD] Memory on Package Support Dual Channel | D23: LPDDR5x, 16GB, 7467MT/s or 8533MT/s [TBD] LPDDR5x, 24GB, 7467MT/s or 8533MT/s [TBD] Memory on Package Support Dual Channel | E23: 24GB LPDDR5X on board Support dual channel memory or LPDDR5x-8533 32GB Memory on Package or 32GB 7500MT/s LPDDR5X (Z1 Extreme)
B24: Storage | C24: PCIe Gen4 M.2 SSD (2280) SSD slot: 1 up to 1TB | D24: PCIe Gen4 NVMe M.2 SSD (2280) SSD Slot *1 Up to 1TB | E24: PCIe Gen4 NVMe M.2TM SSD [2280] SSD slot: 2 Up to 1 TB
B25: Sensor | C25: G+Gyrosensor: 6-Axis IMU * 2 | D25: G+Gyrosensor: 6-Axis IMU *2 | E25: 1x Fingerprint
B27: Wi-Fi | C27: Wi-Fi7 Intel Killer 1775s | D27: Wi-Fi 7 Intel Killer 1775s | E27: Intel® Killer™ AX Wi-Fi 6E
B28: Bluetooth | C28: 5.4 | D28: 5.4 | E28: 5.3
B30: Battery [W] | C30: 80 Whrs [4S1P], 4-cell Li-ion 60 Whrs [4S1P], 4-cell Li-ion | D30: 80 Whrs [4S1P], 4-cell Li-ion 60 Whrs [4S1P], 4-cell Li-ion | E30: 80WHrs, 4S1P, 4-cell Li-ion 6-Cell, 54.5 Battery (Whr) 3-cell, 55.5WHr
B31: AC Power Adapter | C31: Option 1 Wall Mount AC Power Adapter, 65W Type-C Power Cord Option 2 Brick: AC Power Adapter, 65W | D31: Option 1 Wall Mount AC Power Adapter, 65W Type-C Power Cord Option 2 Brick: AC Power Adapter, 65W | E31: TYPE-C, 65W AC Adapter, Output: 20V DC, 3.25A, 65W, Input: 100~240V AC 50/60Hz universal
B32: Control/Input | C32: Connectivity (control & input): - Function button * 4 - Direction button (D-pad) (up/down/left/right) - A/B/X/Y button - Power Button (with fingerprint) - Volume button (+/-) - L & R full-size analog Joystick - L & R hall effect analog triggers - L & R bumpers - L & R Macro button | D32: XBOX Game Bar Widget button. PredatorSense button. View button. Menu button. D-Pad. A B X Y Button. Power button with Finger Print. Volume button(+/-). L & R full-size analog Joysticks. L & R Hall effect analog triggers. L & R bumpers. L & R Macro Button. L & R Adjustable Trigger Switches. | E32: View button Menu button L & R Hall Effect analog triggers L & R bumpers D-pad Command Center button Armoury Crate button A B X Y buttons 2 x assignable grip buttons Thumbsticks: 2 x full-size analog sticks Haptics: HD haptics Gyro: 6-Axis IMU 6-Axis IMU D-pad HD haptics L & R Hall Effect analog triggers L & R bumpers MSI Center M button Macro button (M1/M2) Menu button Quick Settings button RGB ABXY buttons RGB L & R Hall Effect analog sticks View button
B33: I/O Ports | C33: Thunderbolt™ 4 *2 UHSS-II micro SD card reader *1 SD 4.0 Support SD, SDXC, SDHC, SDUC 3.5mm Audio Jack (combo) *1 | D33: Thunderbolt™ 4 *2 UHS-II micro SD card reader *1 SD 4.0 Support SD, SDXC, SDHC, SDUC 3.5mm Audio Jack (combo) *1 | E33: Headphone/mic combo 2x USB4 (USB 40Gbps, DisplayPort™ 1.4, Power Delivery 3.0) MicroSD card reader 1x 3.5mm Combo Audio Jack 1x USB 3.2 Gen 2 Type-C support DisplayPort™ / power delivery 1x Type C support USB 4 (Thunderbolt™ 4 compliance, DisplayPort™ 1.4 with Freesync support, Power Delivery 3.0) 1x UHS-II microSD card reader (supports SD, SDXC and SDHC) 1x Micro SD Card Reader 2x Thunderbolt™ 4 (DisplayPort™/ Power Delivery 3.0)
B34: Touchpad | C34: N/A
B36: Audio | C36: codec ALC712 Combo Jack Speaker: 2W * 2 Mic * 2 DTS X: Ultra & Hi-Res Acer Purified Voice | D36: 2W Speaker *2 Realtek ALC712 DTS:X Ultra & Hi-Res Mic(onboard) *2 Acer PurifiedVoice | E36: 2x2W Integrated Speaker System or Smart Amp Technology Hi-Res certification (for headphone) Dolby Atmos AI noise-canceling technology Built-in array microphone 2-speaker system with Smart Amplifier Technology
B38: OS | C38: Windows 11 Home | D38: Windows 11 Home | E38: Windows 11 Home
B39: PredatorSense/NitroSense Version | C39: PredatorSense | D39: PredatorSense | E39: v5.0.1157
B40: Xbox Game Pass | C40: 2 Month XBOX Game Pass Premium 2 Month XBOX Game Pass Ulitmate 2 Month PC Game Pass [TBD] | D40: 2 Month XBOX Game Pass Premium 2 Month XBOX Game Pass Ulitmate 2 Month PC Game Pass [TBD] | E40: Xbox Game Pass Premium_3 months
B42: Material [PCR %] | C42: Plastic [No PCR] | D42: Plastic [No PCR] | E42: A: Aluminum (PCR 30%) B: Plastic C: Aluminum (PCR 30%) D: Plastic
B43: Dimension [W*D*H] | C43: 292 x 112.7~123 x 28.5~48.4 mm | D43: 299 x 127.4 x 28.5/58.37mm | E43: 22.6mm x 127.55mm x 299mm
B44: Weight | C44: <750g with 80Wh battery (TBD) <700g with 60Wh battery (TBD) | D44: <810g with 80Whr battery <770g with 60Whr battery | E44: 675 g 740g
B45: Color | C45: Black | D45: Black | E45: Black
B50: C Build | C50: May/M ~Jun (TBD) | D50: May/M (TBD)
B51: FCS | C51: Early Q3, 2026 | D51: June, 2026 | E51: Q3 2026
B52: SPEC version | E52: v6-4
B53: PM | C53: Phoebe | D53: Ken | E53: Pan, Albert
B55: KSP Bullets | C55: 1 | D55: 1 | E55: 1. Up to Intel® Core™ Ultra 9 processor 290HX Plus
C56: 2 | D56: 2 | E56: 2. Up to NVIDIA® GeForce RTX™ 5080 Laptop GPU (1334 TOPS)
C57: 3 | D57: 3 | E57: 3. Thin Metal Chassis Design <18.9mm
...

Sheet LAPTOP 2025
B2: MASTER SPEC SHEET - 2025 GAMING LAPTOP PROJECTS
E4: RX
C5: Helios 16 AI | D5: Helios 18 AI | E5: Helios Neo 14 AI | F5: Helios Neo 16 AI | G5: Helios Neo 18 AI | H5: Helios Neo 16S AI | I5: Triton 14 AI | J5: Triton Neo 16 AI | K5: Nitro 16 AI | L5: Nitro 16S AI | M5: Nitro 18 AI | N5: Nitro V 14 | O5: Nitro V 14 AI | P5: Nitro V 16 | Q5: Nitro V 16 AI | R5: Nitro V 17 AI | S5: NITRO V 15 | T5: NITRO V 15 AI | U5: NITRO V 16S | V5: NITRO V 16S AI | W5: NITRO V 14S | X5: NITRO V 14S
C6: PH16-73 | D6: PH18-73 | E6: PHN14-71 | F6: PHN16-73 | G6: PHN18-72 | H6: PHN16S-71 | I6: PT14-52T | J6: PTN16-71 | K6: AN16-61 | L6: AN16S-61 | M6: AN18-61 | N6: ANV14-71 | O6: ANV14-62 (Krackan Point) ANV14-41 (Hawk Point) | P6: ANV16-72 | Q6: ANV16-61 (Krackan Point) ANV16-42 (Hawk Point) | R6: ANV17-61 (Krackan Point) ANV17-41 (Hawk Point) | S6: ANV15-52 | T6: ANV15-42 | U6: ANV16S-71 | V6: ANV16S-61 (Strix Point) ANV16S-41 (Hawk Point) | W6: ANV14S-71 | X6: ANV14S-61
B7: SPEC | C7: Emira_ARX | D7: Vantage_ARX | E7: Panamera_ARH | F7: Macan_ARX | G7: iX1_ARX | H7: FTYPE_ARX | I7: Mulliner_LNV | J7: Cybertruck_ARH | K7: EV9_SKF (AMD) | L7: EV3_SKF (AMD) | M7: GLC_SKF (AMD) | N7: Enyaq_RTH (INTEL) | O7: Enyaq_SKF (AMD) | P7: RX_RTH (INTEL) | Q7: RX_SKF (AMD) | R7: SU7_SKF (AMD) | S7: Sportage_RTH | T7: Sportage_HKH | U7: BRZ_RTH | V7: BRZ_SKF | W7: Kodiaq_RTH | X7: Kodiaq_SKF
B9: Unique Feature | C9: MegKey 4.0 6th Gen AeroBlade 3D Fan Thunderbolt 5 | D9: MegKey 4.0 6th Gen AeroBlade 3D Fan Thunderbolt 5 | H9: Slim | I9: Copilot+ PC NVIDIA Studio Premium Driver 6th Gen AeroBlade 3D fan x 2 Graphene TIM Vapor Chamber Touch Screen Calman verified Haptic touchpad with Stylus pen 6 speakers audio design Human Presence Detection [HPD] | J9: Studio driver Calman | K9: Copilot+ PC | L9: Copilot+ PC Slim | M9: Copilot+ PC | N9: N/A | O9: Copilot+ PC | P9: N/A | Q9: Copilot+ PC | R9: Copilot+ PC | S9: N/A | T9: N/A | U9: slim | V9: Slim Copilot+ PC
K10: N/A | L10: N/A | M10: N/A | N10: N/A | O10: N/A | P10: N/A | Q10: N/A | R10: N/A | S10: N/A | T10: f | U10: N/A | V10: N/A
